[2024-12-17 17:58:19,630] 85 root - ERROR - Error occurred: Traceback (most recent call last):
  File "C:\Users\ACER\mcqq\StreamlitAPP.py", line 39, in <module>
    response = generate_evaluate_chain(
  File "C:\Users\ACER\mcqq\env\lib\site-packages\langchain_core\_api\deprecation.py", line 180, in warning_emitting_wrapper
    return wrapped(*args, **kwargs)
  File "C:\Users\ACER\mcqq\env\lib\site-packages\langchain\chains\base.py", line 380, in __call__
    return self.invoke(
  File "C:\Users\ACER\mcqq\env\lib\site-packages\langchain\chains\base.py", line 163, in invoke
    raise e
  File "C:\Users\ACER\mcqq\env\lib\site-packages\langchain\chains\base.py", line 153, in invoke
    self._call(inputs, run_manager=run_manager)
  File "C:\Users\ACER\mcqq\env\lib\site-packages\langchain\chains\sequential.py", line 104, in _call
    outputs = chain(known_values, return_only_outputs=True, callbacks=callbacks)
  File "C:\Users\ACER\mcqq\env\lib\site-packages\langchain_core\_api\deprecation.py", line 180, in warning_emitting_wrapper
    return wrapped(*args, **kwargs)
  File "C:\Users\ACER\mcqq\env\lib\site-packages\langchain\chains\base.py", line 380, in __call__
    return self.invoke(
  File "C:\Users\ACER\mcqq\env\lib\site-packages\langchain\chains\base.py", line 163, in invoke
    raise e
  File "C:\Users\ACER\mcqq\env\lib\site-packages\langchain\chains\base.py", line 153, in invoke
    self._call(inputs, run_manager=run_manager)
  File "C:\Users\ACER\mcqq\env\lib\site-packages\langchain\chains\llm.py", line 125, in _call
    response = self.generate([inputs], run_manager=run_manager)
  File "C:\Users\ACER\mcqq\env\lib\site-packages\langchain\chains\llm.py", line 137, in generate
    return self.llm.generate_prompt(
  File "C:\Users\ACER\mcqq\env\lib\site-packages\langchain_core\language_models\chat_models.py", line 777, in generate_prompt
    return self.generate(prompt_messages, stop=stop, callbacks=callbacks, **kwargs)
  File "C:\Users\ACER\mcqq\env\lib\site-packages\langchain_core\language_models\chat_models.py", line 634, in generate
    raise e
  File "C:\Users\ACER\mcqq\env\lib\site-packages\langchain_core\language_models\chat_models.py", line 624, in generate
    self._generate_with_cache(
  File "C:\Users\ACER\mcqq\env\lib\site-packages\langchain_core\language_models\chat_models.py", line 846, in _generate_with_cache
    result = self._generate(
  File "C:\Users\ACER\mcqq\env\lib\site-packages\langchain_groq\chat_models.py", line 473, in _generate
    response = self.client.create(messages=message_dicts, **params)
  File "C:\Users\ACER\mcqq\env\lib\site-packages\groq\resources\chat\completions.py", line 298, in create
    return self._post(
  File "C:\Users\ACER\mcqq\env\lib\site-packages\groq\_base_client.py", line 1263, in post
    return cast(ResponseT, self.request(cast_to, opts, stream=stream, stream_cls=stream_cls))
  File "C:\Users\ACER\mcqq\env\lib\site-packages\groq\_base_client.py", line 955, in request
    return self._request(
  File "C:\Users\ACER\mcqq\env\lib\site-packages\groq\_base_client.py", line 1058, in _request
    raise self._make_status_error_from_response(err.response) from None
groq.InternalServerError: Error code: 503 - {'error': {'message': 'Service Unavailable', 'type': 'internal_server_error'}}

